Workbook

Sheet Contagem
A1: 🎽 ESTOQUE DE CAMISETAS — CONGRESSO 2026
A2: Preencha a coluna FÍSICO (amarelo) com a contagem real. A diferença é calculada automaticamente.
A3: ▶ CLIQUE AQUI PARA VER A LISTA DE FALTANTES ▶
A4: Layout | B4: Categoria | C4: Tamanho | D4: Pedidos | E4: Físico (contado) | F4: Falta p/ Fabricar | G4: Status
A5: Layout A | B5: Normal | C5: P | D5: 2 | E5: 0 | F5: =MAX(0,D5-E5) -> 2 | G5: =IF(E5=0,"—",IF(F5>0,"⚠ FALTA",IF(E5>D5,"+ SOBRA","✓ OK"))) -> —
A6: Layout A | B6: Normal | C6: M | D6: 6 | E6: 0 | F6: =MAX(0,D6-E6) -> 6 | G6: =IF(E6=0,"—",IF(F6>0,"⚠ FALTA",IF(E6>D6,"+ SOBRA","✓ OK"))) -> —
A7: Layout A | B7: Normal | C7: G | D7: 13 | E7: 0 | F7: =MAX(0,D7-E7) -> 13 | G7: =IF(E7=0,"—",IF(F7>0,"⚠ FALTA",IF(E7>D7,"+ SOBRA","✓ OK"))) -> —
A8: Layout A | B8: Normal | C8: GG | D8: 3 | E8: 0 | F8: =MAX(0,D8-E8) -> 3 | G8: =IF(E8=0,"—",IF(F8>0,"⚠ FALTA",IF(E8>D8,"+ SOBRA","✓ OK"))) -> —
A9: Layout A | B9: Normal | C9: EG | D9: 3 | E9: 0 | F9: =MAX(0,D9-E9) -> 3 | G9: =IF(E9=0,"—",IF(F9>0,"⚠ FALTA",IF(E9>D9,"+ SOBRA","✓ OK"))) -> —
A10: Layout A | B10: Normal | C10: EXG | D10: 1 | E10: 0 | F10: =MAX(0,D10-E10) -> 1 | G10: =IF(E10=0,"—",IF(F10>0,"⚠ FALTA",IF(E10>D10,"+ SOBRA","✓ OK"))) -> —
A11: Layout A | B11: Babylook | C11: P | D11: 1 | E11: 0 | F11: =MAX(0,D11-E11) -> 1 | G11: =IF(E11=0,"—",IF(F11>0,"⚠ FALTA",IF(E11>D11,"+ SOBRA","✓ OK"))) -> —
A12: Layout A | B12: Babylook | C12: M | D12: 5 | E12: 0 | F12: =MAX(0,D12-E12) -> 5 | G12: =IF(E12=0,"—",IF(F12>0,"⚠ FALTA",IF(E12>D12,"+ SOBRA","✓ OK"))) -> —
A13: Layout A | B13: Babylook | C13: G | D13: 3 | E13: 0 | F13: =MAX(0,D13-E13) -> 3 | G13: =IF(E13=0,"—",IF(F13>0,"⚠ FALTA",IF(E13>D13,"+ SOBRA","✓ OK"))) -> —
A14: Layout A | B14: Babylook | C14: GG | D14: 4 | E14: 0 | F14: =MAX(0,D14-E14) -> 4 | G14: =IF(E14=0,"—",IF(F14>0,"⚠ FALTA",IF(E14>D14,"+ SOBRA","✓ OK"))) -> —
A15: Layout A | B15: Babylook | C15: EG | D15: 3 | E15: 0 | F15: =MAX(0,D15-E15) -> 3 | G15: =IF(E15=0,"—",IF(F15>0,"⚠ FALTA",IF(E15>D15,"+ SOBRA","✓ OK"))) -> —
A16: Layout A | B16: Babylook | C16: EXG | D16: 5 | E16: 0 | F16: =MAX(0,D16-E16) -> 5 | G16: =IF(E16=0,"—",IF(F16>0,"⚠ FALTA",IF(E16>D16,"+ SOBRA","✓ OK"))) -> —
... A65: Layout C | B65: Infantil | C65: 12 | D65: 4 | E65: 0 | F65: =MAX(0,D65-E65) -> 4 | G65: =IF(E65=0,"—",IF(F65>0,"⚠ FALTA",IF(E65>D65,"+ SOBRA","✓ OK"))) -> —
A66: TOTAL GERAL | D66: =SUM(D5:D65) -> 305 | E66: =SUM(E5:E65) -> 0 | F66: =SUM(F5:F65) -> 305

Sheet Lista Faltantes
A1: 🏭 LISTA PARA FABRICAÇÃO — ITENS FALTANTES
A2: ✅ Esta lista atualiza automaticamente conforme você preenche o Físico na aba Contagem
A3: Layout | B3: Categoria | C3: Tamanho | D3: Pedidos | E3: Físico | F3: FALTA P/ FABRICAR
A4: =IFERROR(IF(ROWS(filter(Contagem!A5:F65,Contagem!F5:F65>0))=0,"✓ Nenhum faltante — estoque completo!",filter(Contagem!A5:F65,Contagem!F5:F65>0,"✓ Nenhum faltante")),"⚠ Atualize para Excel 365 ou use a aba Para Fabricação") -> ⚠ Atualize para Excel 365 ou use a aba Para Fabricação
A6: ─── Compatível com todas as versões do Excel ─────────────────────────────────────
A7: =Contagem!A5 -> Layout A | B7: =Contagem!B5 -> Normal | C7: =Contagem!C5 -> P | D7: =Contagem!D5 -> 2 | E7: =Contagem!E5 -> 0 | F7: =Contagem!F5 -> 2
A8: =Contagem!A6 -> Layout A | B8: =Contagem!B6 -> Normal | C8: =Contagem!C6 -> M | D8: =Contagem!D6 -> 6 | E8: =Contagem!E6 -> 0 | F8: =Contagem!F6 -> 6
A9: =Contagem!A7 -> Layout A | B9: =Contagem!B7 -> Normal | C9: =Contagem!C7 -> G | D9: =Contagem!D7 -> 13 | E9: =Contagem!E7 -> 0 | F9: =Contagem!F7 -> 13
A10: =Contagem!A8 -> Layout A | B10: =Contagem!B8 -> Normal | C10: =Contagem!C8 -> GG | D10: =Contagem!D8 -> 3 | E10: =Contagem!E8 -> 0 | F10: =Contagem!F8 -> 3
A11: =Contagem!A9 -> Layout A | B11: =Contagem!B9 -> Normal | C11: =Contagem!C9 -> EG | D11: =Contagem!D9 -> 3 | E11: =Contagem!E9 -> 0 | F11: =Contagem!F9 -> 3
A12: =Contagem!A10 -> Layout A | B12: =Contagem!B10 -> Normal | C12: =Contagem!C10 -> EXG | D12: =Contagem!D10 -> 1 | E12: =Contagem!E10 -> 0 | F12: =Contagem!F10 -> 1
A13: =Contagem!A11 -> Layout A | B13: =Contagem!B11 -> Babylook | C13: =Contagem!C11 -> P | D13: =Contagem!D11 -> 1 | E13: =Contagem!E11 -> 0 | F13: =Contagem!F11 -> 1
A14: =Contagem!A12 -> Layout A | B14: =Contagem!B12 -> Babylook | C14: =Contagem!C12 -> M | D14: =Contagem!D12 -> 5 | E14: =Contagem!E12 -> 0 | F14: =Contagem!F12 -> 5
A15: =Contagem!A13 -> Layout A | B15: =Contagem!B13 -> Babylook | C15: =Contagem!C13 -> G | D15: =Contagem!D13 -> 3 | E15: =Contagem!E13 -> 0 | F15: =Contagem!F13 -> 3
A16: =Contagem!A14 -> Layout A | B16: =Contagem!B14 -> Babylook | C16: =Contagem!C14 -> GG | D16: =Contagem!D14 -> 4 | E16: =Contagem!E14 -> 0 | F16: =Contagem!F14 -> 4
A17: =Contagem!A15 -> Layout A | B17: =Contagem!B15 -> Babylook | C17: =Contagem!C15 -> EG | D17: =Contagem!D15 -> 3 | E17: =Contagem!E15 -> 0 | F17: =Contagem!F15 -> 3
A18: =Contagem!A16 -> Layout A | B18: =Contagem!B16 -> Babylook | C18: =Contagem!C16 -> EXG | D18: =Contagem!D16 -> 5 | E18: =Contagem!E16 -> 0 | F18: =Contagem!F16 -> 5
... A67: =Contagem!A65 -> Layout C | B67: =Contagem!B65 -> Infantil | C67: =Contagem!C65 -> 12 | D67: =Contagem!D65 -> 4 | E67: =Contagem!E65 -> 0 | F67: =Contagem!F65 -> 4
A68: TOTAL A FABRICAR | D68: =Contagem!D66 -> 305 | E68: =Contagem!E66 -> 0 | F68: =Contagem!F66 -> 305
A70: 💡 DICA: Use Dados → AutoFiltro na aba "Contagem" e filtre Falta > 0 para a versão impressa. Ou use Ctrl+P nesta aba — os itens com Falta = 0 ficam invisíveis na impressão.

Sheet Resumo por Layout
A1: 📊 RESUMO POR LAYOUT — PEDIDOS vs FÍSICO
A3: Layout A
A4: Layout | B4: Categoria | C4: Tamanho | D4: Pedidos | E4: Físico | F4: Falta
A5: =Contagem!A5 -> Layout A | B5: =Contagem!B5 -> Normal | C5: =Contagem!C5 -> P | D5: =Contagem!D5 -> 2 | E5: =Contagem!E5 -> 0 | F5: =Contagem!F5 -> 2
A6: =Contagem!A6 -> Layout A | B6: =Contagem!B6 -> Normal | C6: =Contagem!C6 -> M | D6: =Contagem!D6 -> 6 | E6: =Contagem!E6 -> 0 | F6: =Contagem!F6 -> 6
A7: =Contagem!A7 -> Layout A | B7: =Contagem!B7 -> Normal | C7: =Contagem!C7 -> G | D7: =Contagem!D7 -> 13 | E7: =Contagem!E7 -> 0 | F7: =Contagem!F7 -> 13
A8: =Contagem!A8 -> Layout A | B8: =Contagem!B8 -> Normal | C8: =Contagem!C8 -> GG | D8: =Contagem!D8 -> 3 | E8: =Contagem!E8 -> 0 | F8: =Contagem!F8 -> 3
A9: =Contagem!A9 -> Layout A | B9: =Contagem!B9 -> Normal | C9: =Contagem!C9 -> EG | D9: =Contagem!D9 -> 3 | E9: =Contagem!E9 -> 0 | F9: =Contagem!F9 -> 3
A10: =Contagem!A10 -> Layout A | B10: =Contagem!B10 -> Normal | C10: =Contagem!C10 -> EXG | D10: =Contagem!D10 -> 1 | E10: =Contagem!E10 -> 0 | F10: =Contagem!F10 -> 1
A11: =Contagem!A11 -> Layout A | B11: =Contagem!B11 -> Babylook | C11: =Contagem!C11 -> P | D11: =Contagem!D11 -> 1 | E11: =Contagem!E11 -> 0 | F11: =Contagem!F11 -> 1
A12: =Contagem!A12 -> Layout A | B12: =Contagem!B12 -> Babylook | C12: =Contagem!C12 -> M | D12: =Contagem!D12 -> 5 | E12: =Contagem!E12 -> 0 | F12: =Contagem!F12 -> 5
A13: =Contagem!A13 -> Layout A | B13: =Contagem!B13 -> Babylook | C13: =Contagem!C13 -> G | D13: =Contagem!D13 -> 3 | E13: =Contagem!E13 -> 0 | F13: =Contagem!F13 -> 3
A14: =Contagem!A14 -> Layout A | B14: =Contagem!B14 -> Babylook | C14: =Contagem!C14 -> GG | D14: =Contagem!D14 -> 4 | E14: =Contagem!E14 -> 0 | F14: =Contagem!F14 -> 4
A15: =Contagem!A15 -> Layout A | B15: =Contagem!B15 -> Babylook | C15: =Contagem!C15 -> EG | D15: =Contagem!D15 -> 3 | E15: =Contagem!E15 -> 0 | F15: =Contagem!F15 -> 3
A16: =Contagem!A16 -> Layout A | B16: =Contagem!B16 -> Babylook | C16: =Contagem!C16 -> EXG | D16: =Contagem!D16 -> 5 | E16: =Contagem!E16 -> 0 | F16: =Contagem!F16 -> 5
... A22: =Contagem!A22 -> Layout A | B22: =Contagem!B22 -> Infantil | C22: =Contagem!C22 -> 14 | D22: =Contagem!D22 -> 1 | E22: =Contagem!E22 -> 0 | F22: =Contagem!F22 -> 1
A23: Total Layout A | D23: =SUM(D5:D22) -> 57 | E23: =SUM(E5:E22) -> 0 | F23: =SUM(F5:F22) -> 57
A25: Layout B
A26: Layout | B26: Categoria | C26: Tamanho | D26: Pedidos | E26: Físico | F26: Falta
A27: =Contagem!A23 -> Layout B | B27: =Contagem!B23 -> Normal | C27: =Contagem!C23 -> P | D27: =Contagem!D23 -> 14 | E27: =Contagem!E23 -> 0 | F27: =Contagem!F23 -> 14
A28: =Contagem!A24 -> Layout B | B28: =Contagem!B24 -> Normal | C28: =Contagem!C24 -> M | D28: =Contagem!D24 -> 16 | E28: =Contagem!E24 -> 0 | F28: =Contagem!F24 -> 16
A29: =Contagem!A25 -> Layout B | B29: =Contagem!B25 -> Normal | C29: =Contagem!C25 -> G | D29: =Contagem!D25 -> 19 | E29: =Contagem!E25 -> 0 | F29: =Contagem!F25 -> 19
A30: =Contagem!A26 -> Layout B | B30: =Contagem!B26 -> Normal | C30: =Contagem!C26 -> GG | D30: =Contagem!D26 -> 6 | E30: =Contagem!E26 -> 0 | F30: =Contagem!F26 -> 6
A31: =Contagem!A27 -> Layout B | B31: =Contagem!B27 -> Normal | C31: =Contagem!C27 -> EG | D31: =Contagem!D27 -> 2 | E31: =Contagem!E27 -> 0 | F31: =Contagem!F27 -> 2
A32: =Contagem!A28 -> Layout B | B32: =Contagem!B28 -> Normal | C32: =Contagem!C28 -> EXG | D32: =Contagem!D28 -> 2 | E32: =Contagem!E28 -> 0 | F32: =Contagem!F28 -> 2
A33: =Contagem!A29 -> Layout B | B33: =Contagem!B29 -> Normal | C33: =Contagem!C29 -> 56 | D33: =Contagem!D29 -> 2 | E33: =Contagem!E29 -> 0 | F33: =Contagem!F29 -> 2
A34: =Contagem!A30 -> Layout B | B34: =Contagem!B30 -> Babylook | C34: =Contagem!C30 -> P | D34: =Contagem!D30 -> 5 | E34: =Contagem!E30 -> 0 | F34: =Contagem!F30 -> 5
A35: =Contagem!A31 -> Layout B | B35: =Contagem!B31 -> Babylook | C35: =Contagem!C31 -> M | D35: =Contagem!D31 -> 10 | E35: =Contagem!E31 -> 0 | F35: =Contagem!F31 -> 10
A36: =Contagem!A32 -> Layout B | B36: =Contagem!B32 -> Babylook | C36: =Contagem!C32 -> G | D36: =Contagem!D32 -> 8 | E36: =Contagem!E32 -> 0 | F36: =Contagem!F32 -> 8
A37: =Contagem!A33 -> Layout B | B37: =Contagem!B33 -> Babylook | C37: =Contagem!C33 -> GG | D37: =Contagem!D33 -> 12 | E37: =Contagem!E33 -> 0 | F37: =Contagem!F33 -> 12
A38: =Contagem!A34 -> Layout B | B38: =Contagem!B34 -> Babylook | C38: =Contagem!C34 -> EG | D38: =Contagem!D34 -> 6 | E38: =Contagem!E34 -> 0 | F38: =Contagem!F34 -> 6
... A48: =Contagem!A44 -> Layout B | B48: =Contagem!B44 -> Infantil | C48: =Contagem!C44 -> 14 | D48: =Contagem!D44 -> 2 | E48: =Contagem!E44 -> 0 | F48: =Contagem!F44 -> 2
A49: Total Layout B | D49: =SUM(D27:D48) -> 123 | E49: =SUM(E27:E48) -> 0 | F49: =SUM(F27:F48) -> 123
A51: Layout C
A52: Layout | B52: Categoria | C52: Tamanho | D52: Pedidos | E52: Físico | F52: Falta
A53: =Contagem!A45 -> Layout C | B53: =Contagem!B45 -> Normal | C53: =Contagem!C45 -> P | D53: =Contagem!D45 -> 12 | E53: =Contagem!E45 -> 0 | F53: =Contagem!F45 -> 12
A54: =Contagem!A46 -> Layout C | B54: =Contagem!B46 -> Normal | C54: =Contagem!C46 -> M | D54: =Contagem!D46 -> 15 | E54: =Contagem!E46 -> 0 | F54: =Contagem!F46 -> 15
A55: =Contagem!A47 -> Layout C | B55: =Contagem!B47 -> Normal | C55: =Contagem!C47 -> G | D55: =Contagem!D47 -> 25 | E55: =Contagem!E47 -> 0 | F55: =Contagem!F47 -> 25
A56: =Contagem!A48 -> Layout C | B56: =Contagem!B48 -> Normal | C56: =Contagem!C48 -> GG | D56: =Contagem!D48 -> 8 | E56: =Contagem!E48 -> 0 | F56: =Contagem!F48 -> 8
A57: =Contagem!A49 -> Layout C | B57: =Contagem!B49 -> Normal | C57: =Contagem!C49 -> EG | D57: =Contagem!D49 -> 2 | E57: =Contagem!E49 -> 0 | F57: =Contagem!F49 -> 2
...
